(venv) jay@Jayakumars-MacBook-Pro JobFinder-Pro % ./scripts/start_celery.sh
-e ╔════════════════════════════════════════╗
-e ║   Starting Celery Worker               ║
-e ╚════════════════════════════════════════╝
-e 
Checking Redis connection...
-e ✅ Redis is running
-e 
✅ Starting Celery Worker...

Usage: celery [OPTIONS] COMMAND [ARGS]...
Try 'celery --help' for help.

Error: Invalid value for '-A' / '--app': 
Unable to load celery application.
While trying to load the module api.app.celery_app the following error occurred:
Traceback (most recent call last):
  File "/Users/jay/Downloads/job/JobFinder-Pro/venv/lib/python3.11/site-packages/pydantic_settings/sources.py", line 252, in __call__
    field_value = self.prepare_field_value(field_name, field, field_value, value_is_complex)
                  ^^^^^^^^^^^^^^^^^^^^^^^^^^^^^^^^^^^^^^^^^^^^^^^^^^^^^^^^^^^^^^^^^^^^^^^^^^
  File "/Users/jay/Downloads/job/JobFinder-Pro/venv/lib/python3.11/site-packages/pydantic_settings/sources.py", line 435, in prepare_field_value
    raise e
  File "/Users/jay/Downloads/job/JobFinder-Pro/venv/lib/python3.11/site-packages/pydantic_settings/sources.py", line 432, in prepare_field_value
    value = self.decode_complex_value(field_name, field, value)
            ^^^^^^^^^^^^^^^^^^^^^^^^^^^^^^^^^^^^^^^^^^^^^^^^^^^
  File "/Users/jay/Downloads/job/JobFinder-Pro/venv/lib/python3.11/site-packages/pydantic_settings/sources.py", line 103, in decode_complex_value
    return json.loads(value)
           ^^^^^^^^^^^^^^^^^
  File "/usr/local/Cellar/python@3.11/3.11.14_1/Frameworks/Python.framework/Versions/3.11/lib/python3.11/json/__init__.py", line 346, in loads
    return _default_decoder.decode(s)
           ^^^^^^^^^^^^^^^^^^^^^^^^^^
  File "/usr/local/Cellar/python@3.11/3.11.14_1/Frameworks/Python.framework/Versions/3.11/lib/python3.11/json/decoder.py", line 337, in decode
    obj, end = self.raw_decode(s, idx=_w(s, 0).end())
               ^^^^^^^^^^^^^^^^^^^^^^^^^^^^^^^^^^^^^^
  File "/usr/local/Cellar/python@3.11/3.11.14_1/Frameworks/Python.framework/Versions/3.11/lib/python3.11/json/decoder.py", line 355, in raw_decode
    raise JSONDecodeError("Expecting value", s, err.value) from None
json.decoder.JSONDecodeError: Expecting value: line 1 column 2 (char 1)

The above exception was the direct cause of the following exception:

Traceback (most recent call last):
  File "/Users/jay/Downloads/job/JobFinder-Pro/venv/lib/python3.11/site-packages/celery/bin/celery.py", line 58, in convert
    return find_app(value)
           ^^^^^^^^^^^^^^^
  File "/Users/jay/Downloads/job/JobFinder-Pro/venv/lib/python3.11/site-packages/celery/app/utils.py", line 386, in find_app
    sym = imp(app)
          ^^^^^^^^
  File "/Users/jay/Downloads/job/JobFinder-Pro/venv/lib/python3.11/site-packages/celery/utils/imports.py", line 109, in import_from_cwd
    return imp(module, package=package)
           ^^^^^^^^^^^^^^^^^^^^^^^^^^^^
  File "/usr/local/Cellar/python@3.11/3.11.14_1/Frameworks/Python.framework/Versions/3.11/lib/python3.11/importlib/__init__.py", line 126, in import_module
    return _bootstrap._gcd_import(name[level:], package, level)
           ^^^^^^^^^^^^^^^^^^^^^^^^^^^^^^^^^^^^^^^^^^^^^^^^^^^^
  File "<frozen importlib._bootstrap>", line 1204, in _gcd_import
  File "<frozen importlib._bootstrap>", line 1176, in _find_and_load
  File "<frozen importlib._bootstrap>", line 1147, in _find_and_load_unlocked
  File "<frozen importlib._bootstrap>", line 690, in _load_unlocked
  File "<frozen importlib._bootstrap_external>", line 940, in exec_module
  File "<frozen importlib._bootstrap>", line 241, in _call_with_frames_removed
  File "/Users/jay/Downloads/job/JobFinder-Pro/api/app/celery_app.py", line 3, in <module>
    from .core.config import settings
  File "/Users/jay/Downloads/job/JobFinder-Pro/api/app/core/config.py", line 66, in <module>
    settings = Settings()
               ^^^^^^^^^^
  File "/Users/jay/Downloads/job/JobFinder-Pro/venv/lib/python3.11/site-packages/pydantic_settings/main.py", line 72, in __init__
    **__pydantic_self__._settings_build_values(
      ^^^^^^^^^^^^^^^^^^^^^^^^^^^^^^^^^^^^^^^^^
  File "/Users/jay/Downloads/job/JobFinder-Pro/venv/lib/python3.11/site-packages/pydantic_settings/main.py", line 160, in _settings_build_values
    return deep_update(*reversed([source() for source in sources]))
                                 ^^^^^^^^^^^^^^^^^^^^^^^^^^^^^^^^
  File "/Users/jay/Downloads/job/JobFinder-Pro/venv/lib/python3.11/site-packages/pydantic_settings/main.py", line 160, in <listcomp>
    return deep_update(*reversed([source() for source in sources]))
                                  ^^^^^^^^
  File "/Users/jay/Downloads/job/JobFinder-Pro/venv/lib/python3.11/site-packages/pydantic_settings/sources.py", line 254, in __call__
    raise SettingsError(
pydantic_settings.sources.SettingsError: error parsing value for field "ALLOWED_EXTENSIONS" from source "EnvSettingsSource"

(venv) jay@Jayakumars-MacBook-Pro JobFinder-Pro % 
